Workbook

Sheet Table ASHA 1
A1: Table no. ASHA 1 Daily reporting format: ASHA (to be submitted to CHO)
A2: District : a | C2: Taluka : a | M2: PHC : a | V2: SC : a | AB2: Village : a
A3: Asha Name : a | V3: Month : a
A4: No | B4: Assessment Indicator | C4: 1 | D4: 2 | E4: 3 | F4: 4 | G4: 5 | H4: 6 | I4: 7 | J4: 8 | K4: 9 | L4: 10 | M4: 11 | N4: 12 | O4: 13 | P4: 14 | Q4: 15 | R4: 16 | S4: 17 | T4: 18 | U4: 19 | V4: 20 | W4: 21 | X4: 22 | Y4: 23 | Z4: 24 | AA4: 25 | AB4: 26 | AC4: 27 | AD4: 28 | AE4: 29 | AF4: 30 | AG4: 31 | AH4: Total
A5: 1 | B5: Proportion of estimated pregnancies registered (In first trimister) | C5: 0 | D5: 0 | E5: 0 | F5: 0 | G5: 0 | H5: 0 | I5: 0 | J5: 0 | K5: 0 | L5: 0 | M5: 0 | N5: 0 | O5: 0 | P5: 0 | Q5: 0 | R5: 0 | S5: 0 | T5: 0 | U5: 1 | V5: 0 | W5: 0 | X5: 0 | Y5: 0 | Z5: 0 | AA5: 0 | AB5: 0 | AC5: 0 | AD5: 0 | AE5: 0 | AF5: 0 | AG5: 0 | AH5: =SUM(C5:AG5) -> 0
A6: 2 | B6: Proportion of pregnant Woman registered who received ANC | C6: 0 | D6: 0 | E6: 0 | F6: 0 | G6: 0 | H6: 0 | I6: 0 | J6: 0 | K6: 1 | L6: 0 | M6: 0 | N6: 0 | O6: 0 | P6: 0 | Q6: 0 | R6: 0 | S6: 0 | T6: 0 | U6: 0 | V6: 0 | W6: 0 | X6: 0 | Y6: 0 | Z6: 0 | AA6: 0 | AB6: 0 | AC6: 0 | AD6: 0 | AE6: 0 | AF6: 0 | AG6: 0 | AH6: =SUM(C6:AG6) -> 0
A7: 3 | B7: Proportion of Newborns who received HBNC visits (When newborn all scheduled 6 HBNC visits are completed to be considered as 1) | C7: 0 | D7: 0 | E7: 0 | F7: 0 | G7: 0 | H7: 0 | I7: 0 | J7: 0 | K7: 0 | L7: 0 | M7: 0 | N7: 0 | O7: 0 | P7: 0 | Q7: 0 | R7: 1 | S7: 0 | T7: 0 | U7: 0 | V7: 0 | W7: 0 | X7: 0 | Y7: 0 | Z7: 0 | AA7: 0 | AB7: 0 | AC7: 0 | AD7: 0 | AE7: 0 | AF7: 0 | AG7: 0 | AH7: =SUM(C7:AG7) -> 0
A8: 4 | B8: Proportion of Children up to 2 years of age who received immunization | C8: 0 | D8: 0 | E8: 0 | F8: 0 | G8: 0 | H8: 0 | I8: 0 | J8: 0 | K8: 0 | L8: 0 | M8: 0 | N8: 0 | O8: 0 | P8: 0 | Q8: 0 | R8: 0 | S8: 0 | T8: 0 | U8: 0 | V8: 0 | W8: 0 | X8: 0 | Y8: 0 | Z8: 0 | AA8: 0 | AB8: 0 | AC8: 0 | AD8: 0 | AE8: 0 | AF8: 0 | AG8: 0 | AH8: =SUM(C8:AG8) -> 0
A9: 5 | B9: Proportion of above 30 years and above whose CBAC form was filled | C9: 1 | D9: 0 | E9: 0 | F9: 0 | G9: 1 | H9: 0 | I9: 1 | J9: 0 | K9: 0 | L9: 0 | M9: 3 | N9: 0 | O9: 3 | P9: 0 | Q9: 0 | R9: 0 | S9: 0 | T9: 0 | U9: 0 | V9: 3 | W9: 0 | X9: 2 | Y9: 3 | Z9: 0 | AA9: 0 | AB9: 5 | AC9: 3 | AD9: 0 | AE9: 0 | AF9: 0 | AG9: 0 | AH9: =SUM(C9:AG9) -> 0
A10: 6 | B10: Proportion of above 30 years individuals screened for Hypertension (including repeat yearly screenings for Hypertension) | C10: 0 | D10: 0 | E10: 0 | F10: 0 | G10: 0 | H10: 1 | I10: 1 | J10: 0 | K10: 0 | L10: 0 | M10: 0 | N10: 0 | O10: 0 | P10: 0 | Q10: 5 | R10: 2 | S10: 0 | T10: 0 | U10: 1 | V10: 1 | W10: 0 | X10: 1 | Y10: 0 | Z10: 0 | AA10: 7 | AB10: 0 | AC10: 0 | AD10: 0 | AE10: 0 | AF10: 3 | AG10: 0 | AH10: =SUM(C10:AG10) -> 0
A11: 7 | B11: Proportion of patient of HYPERTENSION on Treatment | C11: 0 | D11: 0 | E11: 0 | F11: 0 | G11: 0 | H11: 0 | I11: 0 | J11: 0 | K11: 0 | L11: 0 | M11: 0 | N11: 0 | O11: 1 | P11: 0 | Q11: 0 | R11: 0 | S11: 0 | T11: 0 | U11: 1 | V11: 0 | W11: 0 | X11: 0 | Y11: 0 | Z11: 0 | AA11: 0 | AB11: 0 | AC11: 3 | AD11: 0 | AE11: 0 | AF11: 0 | AG11: 0 | AH11: =SUM(C11:AG11) -> 0
A12: 8 | B12: Proportion of above 30 years individuals screened for Diabetes Mellitus | C12: 4 | D12: 0 | E12: 0 | F12: 0 | G12: 0 | H12: 1 | I12: 0 | J12: 0 | K12: 0 | L12: 0 | M12: 0 | N12: 0 | O12: 0 | P12: 2 | Q12: 2 | R12: 10 | S12: 0 | T12: 0 | U12: 0 | V12: 0 | W12: 0 | X12: 2 | Y12: 0 | Z12: 0 | AA12: 0 | AB12: 0 | AC12: 2 | AD12: 0 | AE12: 0 | AF12: 1 | AG12: 1 | AH12: =SUM(C12:AG12) -> 0
A13: 9 | B13: Proportion of patient of Diabetes Mellitus on Treatment | C13: 0 | D13: 0 | E13: 0 | F13: 0 | G13: 0 | H13: 1 | I13: 0 | J13: 1 | K13: 0 | L13: 0 | M13: 0 | N13: 0 | O13: 1 | P13: 0 | Q13: 0 | R13: 0 | S13: 0 | T13: 0 | U13: 0 | V13: 0 | W13: 0 | X13: 0 | Y13: 0 | Z13: 0 | AA13: 0 | AB13: 0 | AC13: 0 | AD13: 0 | AE13: 0 | AF13: 1 | AG13: 0 | AH13: =SUM(C13:AG13) -> 0
A14: 10 | B14: Proportion of cases referred for TB Screening | C14: 0 | D14: 1 | E14: 2 | F14: 0 | G14: 0 | H14: 0 | I14: 1 | J14: 0 | K14: 0 | L14: 1 | M14: 3 | N14: 0 | O14: 2 | P14: 0 | Q14: 0 | R14: 1 | S14: 0 | T14: 0 | U14: 0 | V14: 0 | W14: 3 | X14: 2 | Y14: 0 | Z14: 0 | AA14: 2 | AB14: 0 | AC14: 0 | AD14: 0 | AE14: 0 | AF14: 0 | AG14: 0 | AH14: =SUM(C14:AG14) -> 0
A15: 11 | B15: Monitoring of Referral cases Upward and Downward | C15: 0 | D15: 0 | E15: 0 | F15: 0 | G15: 0 | H15: 0 | I15: 0 | J15: 0 | K15: 0 | L15: 0 | M15: 0 | N15: 0 | O15: 0 | P15: 0 | Q15: 0 | R15: 0 | S15: 0 | T15: 1 | U15: 0 | V15: 0 | W15: 0 | X15: 0 | Y15: 0 | Z15: 0 | AA15: 0 | AB15: 0 | AC15: 0 | AD15: 0 | AE15: 0 | AF15: 0 | AG15: 0 | AH15: =SUM(C15:AG15) -> 0
A16: 12 | B16: HWC Teleconsulatation services provided | C16: 0 | D16: 0 | E16: 0 | F16: 0 | G16: 0 | H16: 0 | I16: 0 | J16: 0 | K16: 0 | L16: 0 | M16: 0 | N16: 0 | O16: 1 | P16: 0 | Q16: 0 | R16: 0 | S16: 0 | T16: 0 | U16: 0 | V16: 0 | W16: 0 | X16: 0 | Y16: 0 | Z16: 0 | AA16: 0 | AB16: 0 | AC16: 0 | AD16: 0 | AE16: 0 | AF16: 0 | AG16: 0 | AH16: =SUM(C16:AG16) -> 0
... A21: 17 | B21: Home visits per month in the catchment area Min 10 home visits per day in Non-Tribal area and Min 5 home visit per day in Tribal area | C21: 0 | D21: 0 | E21: 0 | F21: 0 | G21: 38 | H21: 0 | I21: 26 | J21: 0 | K21: 0 | L21: 0 | M21: 0 | N21: 26 | O21: 2 | P21: 0 | Q21: 45 | R21: 0 | S21: 0 | T21: 6 | U21: 0 | V21: 0 | W21: 17 | X21: 3 | Y21: 5 | Z21: 32 | AA21: 12 | AB21: 3 | AC21: 0 | AD21: 0 | AE21: 0 | AF21: 0 | AG21: 9 | AH21: =SUM(C21:AG21) -> 0
A22: Declaration- I hereby declare that the information furnished is correct.I am aware that if information furnished is found to be false, strict action may be taken against me.
S28: Name & Signature of ASHA
S29: Date - / / 202

Sheet Table ASHA 2
A1: TABLE - ASHA-2
A2: Performance Linked Payments (PLP) for ASHA
B3: Financial Year | C3: 2024-25 | D3: Month : a
B4: Institute Name: | D4: Validation Officer Name: | H4: Asha Name : a
A5: No | B5: Assessment Indicator | C5: Defination | D5: Source of Verification/ Reporting | E5: Performance as per DPR Sheet | F5: Denominator as per definition | G5: % achievement | H5: Service Delivery Output of Incentive Payment | I5: Applicable Incentive | J5: Payment as per Achievement (Rs. )
A6: 1 | B6: Proportion of estimated pregnancies registered (In first trimister) | C6: Numerator: Number of pregnant women registered for ANC / Denominator – Total no. of estimated pregnancies *100 | D6: ANMOL/ RCH Portal/HWC -Sub Centre register | E6: ='Table ASHA 1'!AH5 -> 0 | F6: =NORM!F3 -> 0 | G6: =E6*100/ROUND(F6,0) -> #DIV/0! | H6: 75% of the estimated pregnancies registered | I6: 45/- | J6: =IF(E6*100/ROUND(F6,0)<75,0,IF(E6*100/ROUND(F6,0)>=100,60,45)) -> #DIV/0!
H7: More than 100% of the estimated pregnancies registered | I7: 60/-
A8: 2 | B8: Proportion of pregnant Woman registered who received ANC | C8: Numerator - Number of pregnant Woman who received ANC services (As per schedule) in a month / Denominator - -Total no of register pregnant Woman whose ANC is due that month identified*100 | D8: ANMOL/ RCH Portal/HWC -Sub Centre register | E8: ='Table ASHA 1'!AH6 -> 0 | F8: =NORM!F4 -> 0 | G8: =E8*100/ROUND(F8,0) -> #DIV/0! | H8: 75% of pregnant Women who received ANC as per Schedule | I8: 45/- | J8: =IF(E8*100/ROUND(F8,0)<75,0,IF(E8*100/ROUND(F8,0)>=100,60,45)) -> #DIV/0!
H9: 100% of pregnant Women who received ANC as per Schedule | I9: 60/-
A10: 3 | B10: Proportion of Newborns who received HBNC visits | C10: Numerator - No.of newborns who received visits (as per schedule) as per HBNC schedule / Denominator - Total no.of newborns * 100 | D10: RCH Portal/HWC-SHC register | E10: ='Table ASHA 1'!AH7 -> 0 | F10: =NORM!F5 -> 0 | G10: =E10*100/ROUND(F10,0) -> #DIV/0! | H10: 75% of newborn received HBNC visits | I10: 45/- | J10: =IF(E10*100/ROUND(F10,0)<75,0,IF(E10*100/ROUND(F10,0)>=100,60,45)) -> #DIV/0!
H11: 100% of newborn received HBNC visits | I11: 60/-
A12: 4 | B12: Proportion of Children up to 2 years of age who received immunization | C12: Numerator - No of children who received immunization (as per Schedule) in a month. / Denominator - Total no of register children whose immunization was due in that month | D12: RCH Portal/HWC-Sub Center register | E12: ='Table ASHA 1'!AH8 -> 0 | F12: =NORM!F6 -> 0 | G12: =E12*100/ROUND(F12,0) -> #DIV/0! | H12: 75% of children received immunization as per schedule | I12: 45/- | J12: =IF(E12*100/ROUND(F12,0)<75,0,IF(E12*100/ROUND(F12,0)>=100,60,45)) -> #DIV/0!
H13: 100% of children received immunization as per schedule | I13: 60/-
A14: 5 | B14: Proportion of above 30 years and above whose CBAC form was filled | C14: Numerator - No of individuals whose CBAC form filled in that month Denominator - Monthly target of total no of 30 years and above individuals whose CBAC form is to be filled Note - * (Once CBAC of all targeted population is done, the HWC would be awareded full points in all subsequent months un that FY) | D14: CPHC NCD Portal | E14: ='Table ASHA 1'!AH9 -> 0 | F14: =NORM!F7 -> 0 | G14: =E14*100/ROUND(F14,0) -> #DIV/0! | H14: 75% of individuals whose CBAC form filled in that month total against 30+ populations | I14: 45/- | J14: =IF(E14*100/ROUND(F14,0)<75,0,IF(E14*100/ROUND(F14,0)>=100,60,45)) -> #DIV/0!
H15: 100% of individuals whose CBAC form filled in that month against total 30+ populations | I15: 60/-
A16: 6 | B16: Proportion of above 30 years individuals screened for Hypertension (including repeat yearly screenings for Hypertension) | C16: Numerator - No. of individuals screened for Hypertension / Denominator- Total population of 30 years & above 30 years of age * 100 Note - (Once hypertension screening of all the targetted population is done, the HWC would be awarded full points in all the subsequent months in that FY) | D16: NCD-CPHC IT Application / HWC-SHS Register | E16: ='Table ASHA 1'!AH10 -> 0 | F16: =NORM!F8 -> 0 | G16: =E16*100/ROUND(F16,0) -> #DIV/0! | H16: 75% of individuals screened for Hypertension out of total 30 years ans above age population | I16: 45/- | J16: =IF(E16*100/ROUND(F16,0)<75,0,IF(E16*100/ROUND(F16,0)>=100,60,45)) -> #DIV/0!
H17: 100% of individuals screened for Hypertension out of total 30 years ans above age population | I17: 60/-
A18: 7 | B18: Proportion of patient of HYPERTENSION on Treatment | C18: Numerator- No. of HTN patient who received follow up care / Denominator- Total No.of HTN patient *100 | D18: NCD-CPHC IT Application / HWC-SHS Register | E18: ='Table ASHA 1'!AH11 -> 0 | F18: =NORM!F9 -> 0 | G18: =E18*100/ROUND(F18,0) -> #DIV/0! | H18: 75 % of patient who received Treatment | I18: 45/- | J18: =IF(E18*100/ROUND(F18,0)<75,0,IF(E18*100/ROUND(F18,0)>=100,60,45)) -> #DIV/0!
H19: 100 % of patient who received Treatment | I19: 60/-
A20: 8 | B20: Proportion of above 30 years individuals screened for Diabetes Mellitus | C20: Numerator - No. of individuals screened for Diabetes Mellitus / Denominator- Monthly target of Total population of 30 years & above individuals to be screened (Once DM screening of all the targetted population is done, the HWC would be awarded full points in all the subsequent months in that FY) | D20: NCD-CPHC IT Application / HWC-SHS Register | E20: ='Table ASHA 1'!AH12 -> 0 | F20: =NORM!F10 -> 0 | G20: =E20*100/ROUND(F20,0) -> #DIV/0! | H20: 75% of individuals screened for Diabetes out of total 30 years ans above age population | I20: 45/- | J20: =IF(E20*100/ROUND(F20,0)<75,0,IF(E20*100/ROUND(F20,0)>=100,60,45)) -> #DIV/0!
H21: 100% of individuals screened for Diabetes out of total 30 years ans above age population | I21: 60/-
A22: 9 | B22: Proportion of patient of Diabetes Mellitus on Treatment | C22: Numerator- No. of DM patient who received follow up care / Denominator- Total No.of DM patient *100 | D22: NCD-CPHC IT Application / HWC-SHS Register | E22: ='Table ASHA 1'!AH13 -> 0 | F22: =NORM!F11 -> 0 | G22: =E22*100/ROUND(F22,0) -> #DIV/0! | H22: 75 % of patient who received Treatment | I22: 45/- | J22: =IF(E22*100/ROUND(F22,0)<75,0,IF(E22*100/ROUND(F22,0)>=100,60,45)) -> #DIV/0!
H23: 100 % of patient who received Treatment | I23: 60/-
A24: 10 | B24: Proportion of cases referred for TB Screening | C24: Numerator- No of suspected TB Cases referred for Diagnosis / Denominator- Total no of patients attented in OPD Target - Minimum 3% cases identified from OPD should have been referred for screening of TB at a higher facility | D24: Nikshay /SHS-HWC Register | E24: ='Table ASHA 1'!AH14 -> 0 | F24: =NORM!F13 -> 0 | G24: =E24*100/ROUND(F24,0) -> #DIV/0! | H24: 75% of suspected TB cases referred against target | I24: 45/- | J24: =IF(E24*100/ROUND(F24,0)<75,0,IF(E24*100/ROUND(F24,0)>=100,60,45)) -> #DIV/0!
H25: 100 % of suspected TB cases referred against target | I25: 60/-
A26: 11 | B26: Monitoring of Referral cases Upward and Downward | C26: Numerator - No of referred cases seen at higher health facility (Upward Refer ) and same cases followed up at SC-HWC / Hone during home visit (Downward refer ) Denominator - Total cases referred | D26: CPHC NCD Portal | E26: ='Table ASHA 1'!AH15 -> 0 | F26: =NORM!F14 -> 0 | G26: =E26*100/ROUND(F26,0) -> #DIV/0! | H26: 75% referred cases seen at higher health facility (Upward Refer ) and same cases followed up at SC-HWC / Hone during home visit (Downward refer ) | I26: 45/- | J26: =IF(E26*100/ROUND(F26,0)<75,0,IF(E26*100/ROUND(F26,0)>=100,60,45)) -> #DIV/0!
H27: 100% referred cases seen at higher health facility (Upward Refer ) and same cases followed up at SC-HWC / Hone during home visit (Downward refer ) | I27: 60/-
A28: 12 | B28: HWC Teleconsulatation services provided | C28: No of Patients provided Teleconsultaion service | D28: E-Sanjieevani | E28: ='Table ASHA 1'!AH16 -> 0 | F28: =NORM!F15 -> 52 | G28: =E28*100/ROUND(F28,0) -> 0 | H28: 75 % of tele consultation done against the target | I28: 45/- | J28: =IF(E28*100/ROUND(F28,0)<75,0,IF(E28*100/ROUND(F28,0)>=100,60,45)) -> 0
H29: 100 % of tele consultation done against the target | I29: 60/-
A30: 13 | B30: Yoga Sessions organised & wellneww activities held as per annual health calender including Health Mela at HWC | C30: No of yoga sessions organized & wellness activities held as per annual health calender including organisation of Health Mela against the target *(Target - 5 yoga sessions per month , total monthly wellness activies as per annual health calender including organization of HEalth Mela) | D30: AB - HWC Portal | E30: ='Table ASHA 1'!AH17 -> 0 | F30: =NORM!F16 -> 5 | G30: =E30*100/ROUND(F30,0) -> 0 | H30: 75 % No of yoga sessions organized & wellness activities held as per annual health calender including organisation of Health Mela against the target | I30: 45/- | J30: =IF(E30*100/ROUND(F30,0)<75,0,IF(E30*100/ROUND(F30,0)>=100,60,45)) -> 0
H31: 100 % No of yoga sessions organized & wellness activities held as per annual health calender including organisation of Health Mela against the target | I31: 60/-
A32: 14 | B32: Monthly JAS Meeting Held at SHC-HWCs | C32: Numerator - No of JAS meetings held Denominator - Total no of JAS meetings planned / expected | D32: AB - HWC Portal | E32: ='Table ASHA 1'!AH18 -> 0 | F32: =NORM!F17 -> 1 | G32: =E32*100/ROUND(F32,0) -> 0 | H32: 100 % JAS meetings held against planned | I32: 50/- | J32: =IF(ROUND(E32,0)>=1,50,0) -> 0
A33: 15 | B33: VHSND held against planned | C33: Numerator - No of VHSND held Denominator - Total no of VHSND Planned Note - (CHO to monitor) | D33: SC - HWC register | E33: ='Table ASHA 1'!AH19 -> 0 | F33: =NORM!F18 -> 3 | G33: =E33*100/ROUND(F33,0) -> 0 | H33: 100 % VHSND held against planned | I33: 50/- | J33: =IF(ROUND(E33,0)>=1,50,0) -> 0
A34: 16 | B34: Number of footfalls in the month | C34: No of OPD cases including new and old cases *(Estimated @60 cases per 1000 population) | D34: AB-HWC portal / SC - HWC register | E34: ='Table ASHA 1'!AH20 -> 0 | F34: =NORM!F19 -> 0 | G34: =E34*100/ROUND(F34,0) -> #DIV/0! | H34: 75% of OPD achived against estimated cases per populations | I34: 45/- | J34: =IF(E34*100/ROUND(F34,0)<75,0,IF(E34*100/ROUND(F34,0)>=100,60,45)) -> #DIV/0!
H35: 100 % of OPD achived against estimated cases per populations | I35: 60/-
A36: 17 | B36: Home visits per month in the catchment area Min 10 home visits per day in Non-Tribal area and Min 5 home visit per day in Tribal area | C36: Numerator - Total Houses visited / Denominator - Against Target | D36: SC - HWC register | E36: ='Table ASHA 1'!AH21 -> 0 | F36: =NORM!F20 -> 220 | G36: =E36*100/ROUND(F36,0) -> 0 | H36: 75 % achivement against target | I36: 45/- | J36: =IF(E36*100/ROUND(F36,0)<75,0,IF(E36*100/ROUND(F36,0)>=100,60,45)) -> 0
H37: 100 % achivement against Target | I37: 60/-
J38: =SUM(J6:J36) -> #DIV/0!
A39: Declaration- I hereby declare that the information furnished is correct.I am aware that if information furnished is found to be false, strict action may be taken against me.
G43: Name & Signature of ASHA
...

Sheet NORM
A1: Performance Based Incentive Indicators for CHO,MPW & ASHA
A2: No | B2: Assessment Indicator | C2: Source of Verification/ Reporting | D2: SC Target | E2: Yearly Target | F2: Monthly Target 100% | G2: Daily Target | H2: 75% of Monthly
A3: 1 | B3: No of estimated pregnancies registered (In first trimister) | C3: ANMOL/ RCH Portal/RCH Register | D3: 11 | E3: =D3 -> 0 | F3: =E3/12 -> 0 | G3: =F3/30 -> 0 | H3: =F3*75% -> 0
A4: 2 | B4: No of pregnant Woman registered who received ANC | C4: ANMOL/ RCH Portal/RCH Register | D4: 11 | E4: =D4 -> 0 | F4: =E4/12 -> 0 | G4: =F4/30 -> 0 | H4: =F4*75% -> 0
A5: 3 | B5: No of Newborns who received HBNC visits | C5: ANMOL/ RCH Portal/RCH Register | D5: =D4*90% -> 0 | E5: =D5 -> 0 | F5: =E5/12 -> 0 | G5: =F5/30 -> 0 | H5: =F5*75% -> 0
A6: 4 | B6: No of Children up to 2 years of age who received immunization (DPT Booster Target - including all previous immunisation completed) | C6: ANMOL/ RCH Portal/RCH Register | D6: 10 | E6: =D6 -> 0 | F6: =E6/12 -> 0 | G6: =F6/30 -> 0 | H6: =F6*75% -> 0
A7: 5 | B7: Proportion of above 30 years and above whose CBAC form was filled | C7: CPHC NCD Portal | D7: 245 | E7: =D7 -> 0 | F7: =E7/12 -> 0 | G7: =F7/30 -> 0 | H7: =F7*75% -> 0
A8: 6 | B8: No of above 30 years individuals screened for Hypertension | C8: CPHC NCD Portal | D8: =E7 -> 0 | E8: =D8 -> 0 | F8: =E8/12 -> 0 | G8: =F8/30 -> 0 | H8: =F8*75% -> 0
A9: 7 | B9: No of patient of HYPERTENSION on Treatment | C9: CPHC NCD Portal | D9: =D8*23.75% -> 0 | E9: =D9 -> 0 | F9: =E9/12 -> 0 | G9: =F9/30 -> 0 | H9: =F9*75% -> 0
A10: 8 | B10: No of above 30 years individuals screened for Diabetes Mellitus | C10: CPHC NCD Portal | D10: =D8 -> 0 | E10: =D10 -> 0 | F10: =E10/12 -> 0 | G10: =F10/30 -> 0 | H10: =F10*75% -> 0
A11: 9 | B11: No of patient of Diabetes Mellitus on Treatment | C11: CPHC NCD Portal | D11: =D10*13% -> 0 | E11: =D11 -> 0 | F11: =E11/12 -> 0 | G11: =F11/30 -> 0 | H11: =F11*75% -> 0
B12: Number of OPD cases (Old+New) | C12: AB-HWC Portal / HWC-SHS Register | D12: 438 | E12: 0 | F12: =D12 -> 0 | G12: 0 | H12: =F12*75% -> 0
A13: 10 | B13: No of cases referred for TB Screening | C13: Nikshay /SHS-HWC Register | D13: =F12*3% -> 0 | E13: 0 | F13: =D13 -> 0 | G13: =F13/30 -> 0 | H13: =F13*75% -> 0
A14: 11 | B14: Monitoring of Referral cases Upward and Downward | C14: CPHC NCD Portal | D14: 1 | E14: 0 | F14: =D14 -> 0 | G14: =F14/30 -> 0 | H14: =F14*75% -> 0
A15: 12 | B15: HWC Teleconsulatation service provide | C15: e-Sanjeevani Portal | D15: =52*12 -> 624 | E15: =D15 -> 624 | F15: =D15/12 -> 52 | G15: =F15/30 -> 1.7333333 | H15: =F15*75% -> 39
A16: 13 | B16: Yoga Sessions organised & wellness activities held as per annual health calender including Health Mela at HWC | C16: AB-HWC Portal | D16: 60 | E16: =D16 -> 60 | F16: =E16/12 -> 5 | G16: =F16/30 -> 0.16666667 | H16: =F16*75% -> 3.75
A17: 14 | B17: Monthly JAS Meeting Held at SHC-HWCs | C17: AB-HWC Portal | D17: 12 | E17: =D17 -> 12 | F17: =E17/12 -> 1 | G17: =F17/30 -> 0.033333333 | H17: =F17*75% -> 0.75
A18: 15 | B18: VHSND held against planned | C18: SC-HWC Register | D18: 36 | E18: =D18 -> 36 | F18: =E18/12 -> 3 | G18: =F18/30 -> 0.1 | H18: =F18*75% -> 2.25
A19: 16 | B19: Number of footfalls in the month | C19: AB-HWC Portal / HWC-SHS Register | D19: 348 | E19: 0 | F19: =D19 -> 0 | G19: =F19/26 -> 0 | H19: =F19*75% -> 0
A20: 17 | B20: Home visits per month in the catchment area Min 10 home visits per day in Non-Tribal area and Min 5 home visit per day in Tribal area | C20: SC-HWC Register | D20: =22*10*12 -> 2640 | E20: =D20 -> 2640 | F20: =E20/12 -> 220 | G20: =F20/22 -> 10 | H20: =F20*75% -> 165
B22: Important Note
B23: 1. Insert RCH ANC Target of your SC in No 1
B24: 2. Insert RCH ANC Target of your SC in No 2
B25: 3. HBNC Scheduled visits 6 for every one single child, per day visited no of Childs to be mentioned in table No 1 No 3
B26: 4. Insert Child Registration Target (DPT Booster-including all previous immunisation completed ) of your SC in No 4
B27: 5 Once CBAC of all targeted population is done, the HWC would be awareded full points in all subsequent months un that FY No 5
B28: 6 37% population above 30 years No 6
B29: 7 23.75% patients need treatment after Final diagnosis for Hypertension including followup patients No 7
B30: 8 37% population above 30 years for DM screening and 13% of DM for treatment including followup No 8
B31: 9 37% population above 30 years for DM screening and 13% of DM for treatment including followup No 9
B32: OPD 6% of total population per month
B33: 10 TB Screening minimum 3 % from OPD Cases in each month No 10
... B40: 17 10 Home visits per day for 26 working days , Individually CHO needs to give home visits
A41: 18 | B41: IMP Note
B42: The population less than 1000 of any HWC SC have target of OPD will be 150
